<?xml version="1.0" encoding="utf-8"?>
<!-- This URDF was automatically created by SolidWorks to URDF Exporter! Originally created by Stephen Brawner (brawner@gmail.com) 
     Commit Version: 1.6.0-4-g7f85cfe  Build Version: 1.6.7995.38578
     For more information, please see http://wiki.ros.org/sw_urdf_exporter -->
<robot
  name="ddrive_navigation_impl">
  <link
    name="base_link">
    <inertial>
      <origin
        xyz="-0.0139424640536014 0.0129876081309735 0.00654203268749143"
        rpy="0 0 0" />
      <mass
        value="1.17456295297781" />
      <inertia
        ixx="0.00223044069648703"
        ixy="-6.32626092012459E-05"
        ixz="2.94658978817516E-20"
        iyy="0.00817476268334436"
        iyz="-8.19168823828385E-20"
        izz="0.00617609099246247" />
    </inertial>
    <visual>
      <origin
        xyz="0 0 0"
        rpy="0 0 0" />
      <geometry>
        <mesh
          filename="package://ddrive_navigation_impl/meshes/base_link.STL" />
      </geometry>
      <material
        name="">
        <color
          rgba="0.792156862745098 0.819607843137255 0.933333333333333 1" />
      </material>
    </visual>
    <collision>
      <origin
        xyz="0 0 0"
        rpy="0 0 0" />
      <geometry>
        <mesh
          filename="package://ddrive_navigation_impl/meshes/base_link.STL" />
      </geometry>
      <surface>
        <friction>
          <ode>
            <mu>1.0</mu>
            <mu2>1.0</mu2>
          </ode>
        </friction>
      </surface>
    </collision>
  </link>
  <link
    name="left_wheel">
    <inertial>
      <origin
        xyz="-1.38777878078145E-17 -6.93889390390723E-18 0.0323201178441002"
        rpy="0 0 0" />
      <mass
        value="0.0346791977367494" />
      <inertia
        ixx="1.41585015301741E-05"
        ixy="-1.27054942088145E-21"
        ixz="5.35088438039888E-22"
        iyy="1.41585015301741E-05"
        iyz="2.90528349791999E-21"
        izz="2.53540976405827E-05" />
    </inertial>
    <visual>
      <origin
        xyz="0 0 0"
        rpy="0 0 0" />
      <geometry>
        <mesh
          filename="package://ddrive_navigation_impl/meshes/left_wheel.STL" />
      </geometry>
      <material
        name="">
        <color
          rgba="1 1 0 1" />
      </material>
    </visual>
    <collision>
      <origin
        xyz="0 0 0"
        rpy="0 0 0" />
      <geometry>
        <mesh
          filename="package://ddrive_navigation_impl/meshes/left_wheel.STL" />
      </geometry>
      <surface>
        <friction>
          <ode>
            <mu>1.0</mu>
            <mu2>1.0</mu2>
          </ode>
        </friction>
      </surface>
    </collision>
  </link>
  <joint
    name="left_joint"
    type="continuous">
    <origin
      xyz="-0.078206903468503 0.0534579673125085 0.0120971032828063"
      rpy="1.5707963267949 0.413063406587512 -3.14159265358979" />
    <parent
      link="base_link" />
    <child
      link="left_wheel" />
    <axis
      xyz="0 0 1" />
  </joint>
  <link
    name="right_wheel">
    <inertial>
      <origin
        xyz="6.93889390390723E-18 1.38777878078145E-17 0.0323201178441002"
        rpy="0 0 0" />
      <mass
        value="0.0346791977367494" />
      <inertia
        ixx="1.41585015301741E-05"
        ixy="2.11758236813575E-21"
        ixz="3.97111338233382E-22"
        iyy="1.41585015301741E-05"
        iyz="1.98976293614101E-22"
        izz="2.53540976405827E-05" />
    </inertial>
    <visual>
      <origin
        xyz="0 0 0"
        rpy="0 0 0" />
      <geometry>
        <mesh
          filename="package://ddrive_navigation_impl/meshes/right_wheel.STL" />
      </geometry>
      <material
        name="">
        <color
          rgba="1 1 0 1" />
      </material>
    </visual>
    <collision>
      <origin
        xyz="0 0 0"
        rpy="0 0 0" />
      <geometry>
        <mesh
          filename="package://ddrive_navigation_impl/meshes/right_wheel.STL" />
      </geometry>
      <surface>
        <friction>
          <ode>
            <mu>1.0</mu>
            <mu2>1.0</mu2>
          </ode>
        </friction>
      </surface>
    </collision>
  </link>
  <joint
    name="right_joint"
    type="continuous">
    <origin
      xyz="-0.0782069034685027 -0.0665420326874914 0.0120971032828061"
      rpy="1.5707963267949 1.19119482376332 0" />
    <parent
      link="base_link" />
    <child
      link="right_wheel" />
    <axis
      xyz="0 0 -1" />
  </joint>
</robot>
