<?xml version="1.0" encoding="utf-8"?>
<!-- This URDF was automatically created by SolidWorks to URDF Exporter! Originally created by Stephen Brawner (brawner@gmail.com) 
     Commit Version: 1.6.0-4-g7f85cfe  Build Version: 1.6.7995.38578
     For more information, please see http://wiki.ros.org/sw_urdf_exporter -->
<robot
  name="my_navigation_impl">
  <link
    name="base_link">
    <inertial>
      <origin
        xyz="-0.00120819397481913 0.00583609620014158 0.0177572450595865"
        rpy="0 0 0" />
      <mass
        value="0.693331823568784" />
      <inertia
        ixx="0.000768852379896162"
        ixy="-5.12753300403153E-20"
        ixz="-5.18241204109562E-06"
        iyy="0.00151231644756755"
        iyz="2.3340928909064E-20"
        izz="0.00186744982908071" />
    </inertial>
    <visual>
      <origin
        xyz="0 0 0"
        rpy="0 0 0" />
      <geometry>
        <mesh
          filename="package://my_navigation_impl/meshes/base_link.STL" />
      </geometry>
      <material
        name="">
        <color
          rgba="0.792156862745098 0.819607843137255 0.933333333333333 1" />
      </material>
    </visual>
    <collision>
      <origin
        xyz="0 0 0"
        rpy="0 0 0" />
      <geometry>
        <mesh
          filename="package://my_navigation_impl/meshes/base_link.STL" />
      </geometry>
    </collision>
  </link>
  <link
    name="FL_wheel">
    <inertial>
      <origin
        xyz="-1.73472347597681E-18 1.38777878078145E-17 0.0323201178441002"
        rpy="0 0 0" />
      <mass
        value="0.0346791977367494" />
      <inertia
        ixx="1.41585015301741E-05"
        ixy="2.01170324972896E-21"
        ixz="2.44696193864003E-22"
        iyy="1.41585015301741E-05"
        iyz="7.0885799208265E-22"
        izz="2.53540976405827E-05" />
    </inertial>
    <visual>
      <origin
        xyz="0 0 0"
        rpy="0 0 0" />
      <geometry>
        <mesh
          filename="package://my_navigation_impl/meshes/FL_wheel.STL" />
      </geometry>
      <material
        name="">
        <color
          rgba="1 1 0 1" />
      </material>
    </visual>
    <collision>
      <origin
        xyz="0 0 0"
        rpy="0 0 0" />
      <geometry>
        <mesh
          filename="package://my_navigation_impl/meshes/FL_wheel.STL" />
      </geometry>
    </collision>
  </link>
  <joint
    name="FL_joint"
    type="continuous">
    <origin
      xyz="0.0644098251287604 0.0558360962001416 0.00982536770135314"
      rpy="-1.5707963267949 1.50486401595057 0" />
    <parent
      link="base_link" />
    <child
      link="FL_wheel" />
    <axis
      xyz="0 0 1" />
  </joint>
  <link
    name="FR_wheel">
    <inertial>
      <origin
        xyz="9.71445146547012E-17 1.59594559789866E-16 0.0323201178441002"
        rpy="0 0 0" />
      <mass
        value="0.0346791977367494" />
      <inertia
        ixx="1.41585015301741E-05"
        ixy="-1.85288457211878E-21"
        ixz="-2.21000106931829E-21"
        iyy="1.41585015301741E-05"
        iyz="1.15665347132748E-21"
        izz="2.53540976405827E-05" />
    </inertial>
    <visual>
      <origin
        xyz="0 0 0"
        rpy="0 0 0" />
      <geometry>
        <mesh
          filename="package://my_navigation_impl/meshes/FR_wheel.STL" />
      </geometry>
      <material
        name="">
        <color
          rgba="1 1 0 1" />
      </material>
    </visual>
    <collision>
      <origin
        xyz="0 0 0"
        rpy="0 0 0" />
      <geometry>
        <mesh
          filename="package://my_navigation_impl/meshes/FR_wheel.STL" />
      </geometry>
    </collision>
  </link>
  <joint
    name="FR_joint"
    type="continuous">
    <origin
      xyz="0.0644098251287605 -0.0441639037998584 0.00982536770135312"
      rpy="1.5707963267949 0.0589239498814076 0" />
    <parent
      link="base_link" />
    <child
      link="FR_wheel" />
    <axis
      xyz="0 0 1" />
  </joint>
  <link
    name="BR_wheel">
    <inertial>
      <origin
        xyz="0 2.08166817117217E-17 0.0323201178441002"
        rpy="0 0 0" />
      <mass
        value="0.0346791977367494" />
      <inertia
        ixx="1.41585015301741E-05"
        ixy="0"
        ixz="2.79360249507235E-22"
        iyy="1.41585015301741E-05"
        iyz="6.39147386862793E-21"
        izz="2.53540976405827E-05" />
    </inertial>
    <visual>
      <origin
        xyz="0 0 0"
        rpy="0 0 0" />
      <geometry>
        <mesh
          filename="package://my_navigation_impl/meshes/BR_wheel.STL" />
      </geometry>
      <material
        name="">
        <color
          rgba="1 1 0 1" />
      </material>
    </visual>
    <collision>
      <origin
        xyz="0 0 0"
        rpy="0 0 0" />
      <geometry>
        <mesh
          filename="package://my_navigation_impl/meshes/BR_wheel.STL" />
      </geometry>
    </collision>
  </link>
  <joint
    name="BR_joint"
    type="continuous">
    <origin
      xyz="-0.0675901748712395 -0.0441639037998584 0.00982536770135312"
      rpy="1.5707963267949 -0.82700358095234 0" />
    <parent
      link="base_link" />
    <child
      link="BR_wheel" />
    <axis
      xyz="0 0 1" />
  </joint>
  <link
    name="BL_wheel">
    <inertial>
      <origin
        xyz="-7.35522753814166E-16 2.98372437868011E-16 0.0323201178441002"
        rpy="0 0 0" />
      <mass
        value="0.0346791977367494" />
      <inertia
        ixx="1.41585015301741E-05"
        ixy="4.12928561786471E-21"
        ixz="2.64541163984239E-21"
        iyy="1.41585015301741E-05"
        iyz="-2.979508546196E-23"
        izz="2.53540976405827E-05" />
    </inertial>
    <visual>
      <origin
        xyz="0 0 0"
        rpy="0 0 0" />
      <geometry>
        <mesh
          filename="package://my_navigation_impl/meshes/BL_wheel.STL" />
      </geometry>
      <material
        name="">
        <color
          rgba="1 1 0 1" />
      </material>
    </visual>
    <collision>
      <origin
        xyz="0 0 0"
        rpy="0 0 0" />
      <geometry>
        <mesh
          filename="package://my_navigation_impl/meshes/BL_wheel.STL" />
      </geometry>
    </collision>
  </link>
  <joint
    name="BL_joint"
    type="continuous">
    <origin
      xyz="-0.0675901748712395 0.0558360962001415 0.00982536770135311"
      rpy="1.5707963267949 0.0913241498042733 -3.14159265358979" />
    <parent
      link="base_link" />
    <child
      link="BL_wheel" />
    <axis
      xyz="0 0 1" />
  </joint>
</robot>