<?xml version="1.0" encoding="utf-8"?>
<!-- This URDF was automatically created by SolidWorks to URDF Exporter! Originally created by Stephen Brawner (brawner@gmail.com) 
     Commit Version: 1.6.0-4-g7f85cfe  Build Version: 1.6.7995.38578
     For more information, please see http://wiki.ros.org/sw_urdf_exporter -->
<robot
  name="my_navigation_impl">
  <link
    name="base_link">
    <inertial>
      <origin
        xyz="-0.00120819397481913 0.00583609620014158 0.0177572450595865"
        rpy="0 0 0" />
      <mass
        value="0.693331823568784" />
      <inertia
        ixx="0.000768852379896162"
        ixy="-5.12753300403153E-20"
        ixz="-5.18241204109562E-06"
        iyy="0.00151231644756755"
        iyz="2.3340928909064E-20"
        izz="0.00186744982908071" />
    </inertial>
    <visual>
      <origin
        xyz="0 0 0"
        rpy="0 0 0" />
      <geometry>
        <mesh
          filename="package://my_navigation_impl/meshes/base_link.STL" />
      </geometry>
      <material
        name="">
        <color
          rgba="0.792156862745098 0.819607843137255 0.933333333333333 1" />
      </material>
    </visual>
    <collision>
      <origin
        xyz="0 0 0"
        rpy="0 0 0" />
      <geometry>
        <mesh
          filename="package://my_navigation_impl/meshes/base_link.STL" />
      </geometry>
    </collision>
  </link>
  <link
    name="FL_wheel">
    <inertial>
      <origin
        xyz="-1.73472347597681E-18 1.38777878078145E-17 0.0323201178441002"
        rpy="0 0 0" />
      <mass
        value="0.0346791977367494" />
      <inertia
        ixx="1.41585015301741E-05"
        ixy="2.01170324972896E-21"
        ixz="2.44696193864003E-22"
        iyy="1.41585015301741E-05"
        iyz="7.0885799208265E-22"
        izz="2.53540976405827E-05" />
    </inertial>
    <visual>
      <origin
        xyz="0 0 0"
        rpy="0 0 0" />
      <geometry>
        <mesh
          filename="package://my_navigation_impl/meshes/FL_wheel.STL" />
      </geometry>
      <material
        name="">
        <color
          rgba="1 1 0 1" />
      </material>
    </visual>
    <collision>
      <origin
        xyz="0 0 0"
        rpy="0 0 0" />
      <geometry>
        <mesh
          filename="package://my_navigation_impl/meshes/FL_wheel.STL" />
      </geometry>
    </collision>
  </link>
  <joint
    name="FL_joint"
    type="continuous">
    <origin
      xyz="0.0644098251287604 0.0558360962001416 0.00982536770135314"
      rpy="-1.5707963267949 1.50486401595057 0" />
    <parent
      link="base_link" />
    <child
      link="FL_wheel" />
    <axis
      xyz="0 0 1" />
  </joint>
  <link
    name="FR_wheel">
    <inertial>
      <origin
        xyz="9.71445146547012E-17 1.59594559789866E-16 0.0323201178441002"
        rpy="0 0 0" />
      <mass
        value="0.0346791977367494" />
      <inertia
        ixx="1.41585015301741E-05"
        ixy="-1.85288457211878E-21"
        ixz="-2.21000106931829E-21"
        iyy="1.41585015301741E-05"
        iyz="1.15665347132748E-21"
        izz="2.53540976405827E-05" />
    </inertial>
    <visual>
      <origin
        xyz="0 0 0"
        rpy="0 0 0" />
      <geometry>
        <mesh
          filename="package://my_navigation_impl/meshes/FR_wheel.STL" />
      </geometry>
      <material
        name="">
        <color
          rgba="1 1 0 1" />
      </material>
    </visual>
    <collision>
      <origin
        xyz="0 0 0"
        rpy="0 0 0" />
      <geometry>
        <mesh
          filename="package://my_navigation_impl/meshes/FR_wheel.STL" />
      </geometry>
    </collision>
  </link>
  <joint
    name="FR_joint"
    type="continuous">
    <origin
      xyz="0.0644098251287605 -0.0441639037998584 0.00982536770135312"
      rpy="1.5707963267949 0.0589239498814076 0" />
    <parent
      link="base_link" />
    <child
      link="FR_wheel" />
    <axis
      xyz="0 0 1" />
  </joint>
  <link
    name="BR_wheel">
    <inertial>
      <origin
        xyz="0 2.08166817117217E-17 0.0323201178441002"
        rpy="0 0 0" />
      <mass
        value="0.0346791977367494" />
      <inertia
        ixx="1.41585015301741E-05"
        ixy="0"
        ixz="2.79360249507235E-22"
        iyy="1.41585015301741E-05"
        iyz="6.39147386862793E-21"
        izz="2.53540976405827E-05" />
    </inertial>
    <visual>
      <origin
        xyz="0 0 0"
        rpy="0 0 0" />
      <geometry>
        <mesh
          filename="package://my_navigation_impl/meshes/BR_wheel.STL" />
      </geometry>
      <material
        name="">
        <color
          rgba="1 1 0 1" />
      </material>
    </visual>
    <collision>
      <origin
        xyz="0 0 0"
        rpy="0 0 0" />
      <geometry>
        <mesh
          filename="package://my_navigation_impl/meshes/BR_wheel.STL" />
      </geometry>
    </collision>
  </link>
  <joint
    name="BR_joint"
    type="continuous">
    <origin
      xyz="-0.0675901748712395 -0.0441639037998584 0.00982536770135312"
      rpy="1.5707963267949 -0.82700358095234 0" />
    <parent
      link="base_link" />
    <child
      link="BR_wheel" />
    <axis
      xyz="0 0 1" />
  </joint>
  <link
    name="BL_wheel">
    <inertial>
      <origin
        xyz="-7.35522753814166E-16 2.98372437868011E-16 0.0323201178441002"
        rpy="0 0 0" />
      <mass
        value="0.0346791977367494" />
      <inertia
        ixx="1.41585015301741E-05"
        ixy="4.12928561786471E-21"
        ixz="2.64541163984239E-21"
        iyy="1.41585015301741E-05"
        iyz="-2.979508546196E-23"
        izz="2.53540976405827E-05" />
    </inertial>
    <visual>
      <origin
        xyz="0 0 0"
        rpy="0 0 0" />
      <geometry>
        <mesh
          filename="package://my_navigation_impl/meshes/BL_wheel.STL" />
      </geometry>
      <material
        name="">
        <color
          rgba="1 1 0 1" />
      </material>
    </visual>
    <collision>
      <origin
        xyz="0 0 0"
        rpy="0 0 0" />
      <geometry>
        <mesh
          filename="package://my_navigation_impl/meshes/BL_wheel.STL" />
      </geometry>
    </collision>
  </link>
  <joint
    name="BL_joint"
    type="continuous">
    <origin
      xyz="-0.0675901748712395 0.0558360962001415 0.00982536770135311"
      rpy="1.5707963267949 0.0913241498042733 -3.14159265358979" />
    <parent
      link="base_link" />
    <child
      link="BL_wheel" />
    <axis
      xyz="0 0 1" />
  </joint>
<gazebo>
  <plugin name="skid_steer_drive_controller" filename="libgazebo_ros_skid_steer_drive.so">
    <updateRate>20.0</updateRate>
    <robotNamespace>/</robotNamespace>
    <leftFrontJoint>FL_joint</leftFrontJoint>
    <rightFrontJoint>FR_joint</rightFrontJoint>
    <leftRearJoint>BL_joint</leftRearJoint>
    <rightRearJoint>BR_joint</rightRearJoint>
    <wheelSeparation>0.4</wheelSeparation>
    <wheelDiameter>0.215</wheelDiameter>
    <robotBaseFrame>base_link</robotBaseFrame>
    <torque>20</torque>
    <topicName>cmd_vel</topicName>
    <broadcastTF>true</broadcastTF>
  </plugin>
</gazebo>

  <!-- Hokuyo Laser -->
  <link name="lidar_link">
    <collision>
      <origin xyz="0 0 0" rpy="0 0 0"/>
      <geometry>
    <box size="0.1 0.1 0.1"/>
      </geometry>
    </collision>

    <visual>
      <origin xyz="0 0 0" rpy="0 0 0"/>
      <geometry>
        <box size="0.05 0.05 0.01"/>
      </geometry>
    </visual>

    <inertial>
      <mass value="1e-5" />
      <origin xyz="0 0 0" rpy="0 0 0"/>
      <inertia ixx="1e-6" ixy="0" ixz="0" iyy="1e-6" iyz="0" izz="1e-6" />
    </inertial>
  </link>

  <joint name="hokuyo_joint" type="fixed">
    <axis xyz="0 1 0" />
    <origin xyz="0 0 0.1" rpy="0 0 0"/>
    <parent link="base_link"/>
    <child link="lidar_link"/>
  </joint>

  <!-- hokuyo -->
  <gazebo reference="lidar_link">
    <sensor type="ray" name="head_hokuyo_sensor">
      <pose>0 0 0.1 0 0 0</pose>
      <visualize>true</visualize>
      <update_rate>20</update_rate>
      <ray>
        <scan>
          <horizontal>
            <samples>720</samples>
            <resolution>1</resolution>
            <min_angle>-3.14159</min_angle>
            <max_angle>3.14159</max_angle>
          </horizontal>
        </scan>
        <range>
          <min>0.20</min>
          <max>10.0</max>
          <resolution>0.01</resolution>
        </range>
        <noise>
          <type>gaussian</type>
          <!-- Noise parameters based on published spec for Hokuyo laser
               achieving "+-30mm" accuracy at range < 10m.  A mean of 0.0m and
               stddev of 0.01m will put 99.7% of samples within 0.03m of the true
               reading. -->
          <mean>0.0</mean>
          <stddev>0.01</stddev>
        </noise>
      </ray>
      <plugin name="gazebo_ros_head_hokuyo_controller" filename="libgazebo_ros_laser.so">
        <topicName>/laser/scan</topicName>
        <frameName>lidar_link</frameName>
      </plugin>
    </sensor>
  </gazebo>


</robot>
